#VRML_SIM R2023b utf8

EXTERNPROTO "https://raw.githubusercontent.com/cyberbotics/webots/R2023b/projects/objects/backgrounds/protos/TexturedBackground.proto"
EXTERNPROTO "https://raw.githubusercontent.com/cyberbotics/webots/R2023b/projects/objects/backgrounds/protos/TexturedBackgroundLight.proto"
EXTERNPROTO "https://raw.githubusercontent.com/cyberbotics/webots/R2023b/projects/objects/floors/protos/RectangleArena.proto"

WorldInfo {
}
Viewpoint {
  orientation -0.252500546514223 0.1040283857681295 0.9619883413869921 2.453910085549084
  position 1.3288851617252995 -1.1356794832822987 1.013547035335895
}
TexturedBackground {
}
TexturedBackgroundLight {
}
RectangleArena {
}
DEF Mobile Robot {
  translation 0 0.25 0
  rotation 0 0 1 3.14159
  children [
    Receiver {
    }
    Emitter {
    }
    GPS {
    }
    HingeJoint {
      jointParameters HingeJointParameters {
        anchor -0.05 0 0.025
      }
      device [
        RotationalMotor {
          name "motor2"
        }
      ]
      endPoint Solid {
        translation -0.05 0 0.025
        rotation 0 1 0 1.57
        children [
          DEF Wheel2 Shape {
            appearance PBRAppearance {
              baseColor 1 0 0
              roughness 1
              metalness 0
            }
            geometry Cylinder {
              height 0.01
              radius 0.025
            }
          }
        ]
        name "wheel2"
        boundingObject USE Wheel2
        physics DEF WheelPhysics2 Physics {
        }
      }
    }
    DEF Body Pose {
      translation 0 0 0.0415
      children [
        Shape {
          appearance PBRAppearance {
            baseColor 0 1 1
            roughness 1
            metalness 0
          }
          geometry Cylinder {
            height 0.08
            radius 0.05
          }
        }
      ]
    }
    HingeJoint {
      jointParameters HingeJointParameters {
        anchor 0.05 0 0.025
      }
      device [
        RotationalMotor {
          name "motor1"
        }
      ]
      endPoint Solid {
        translation 0.05 0 0.025
        rotation 0 1 0 1.57
        children [
          DEF Wheel1 Shape {
            appearance PBRAppearance {
              baseColor 1 0 0
              roughness 1
              metalness 0
            }
            geometry Cylinder {
              height 0.01
              radius 0.025
            }
          }
        ]
        name "wheel1"
        boundingObject USE Wheel1
        physics DEF WheelPhysics1 Physics {
        }
      }
    }
  ]
  name "robot1"
  boundingObject USE Body
  physics Physics {
  }
  controller "communication"
}
DEF Stationary Robot {
  translation 0 -0.25 0
  children [
    GPS {
    }
    Emitter {
    }
    Receiver {
    }
    USE Body
  ]
  name "robot2"
  boundingObject USE Body
  physics Physics {
  }
  controller "communication"
}
